<?xml version="1.0" ?>
<robot xmlns:xacro="http://www.ros.org/wiki/xacro">
    <!-- I made this file just because I felt that having it four times in the intake was a *bad* idea. Feel free to give better ideas. -->
    <xacro:macro name="versaroller" params="prefix parent *origin">

    <link name="intake_rollerbar_${prefix}_link">
        <collision>
            <geometry>
                <cylinder length="0.575" radius="0.016"/>
            </geometry>
            <!-- <material name="ghost" /> -->
        </collision>
    </link>


    <joint name="intake_rollerbar_${prefix}_joint" type="continuous">
        <parent link="${parent}" />
        <child link="intake_rollerbar_${prefix}_link" />
        <xacro:insert_block name="origin" />
        <axis xyz="0 0 -1" />
        <dynamics friction="0.1" />
    </joint>
    

    </xacro:macro>
</robot>